INFO     common.basepage:basepage.py:24 等待元素 ('xpath', '//input[@class="s-input"]') 可见。
ERROR    common.basepage:basepage.py:35 等待元素可见失败：
Traceback (most recent call last):
  File "D:\B2B\common\basepage.py", line 28, in wait_eleVisible
    WebDriverWait(self.driver,timeout,frequency).until(EC.visibility_of_element_located(loc))
  File "E:\Python3\lib\site-packages\selenium\webdriver\support\wait.py", line 71, in until
    value = method(self._driver)
  File "E:\Python3\lib\site-packages\selenium\webdriver\support\expected_conditions.py", line 128, in __call__
    return _element_if_visible(_find_element(driver, self.locator))
  File "E:\Python3\lib\site-packages\selenium\webdriver\support\expected_conditions.py", line 415, in _find_element
    raise e
  File "E:\Python3\lib\site-packages\selenium\webdriver\support\expected_conditions.py", line 411, in _find_element
    return driver.find_element(*by)
  File "E:\Python3\lib\site-packages\selenium\webdriver\remote\webdriver.py", line 978, in find_element
    'value': value})['value']
  File "E:\Python3\lib\site-packages\selenium\webdriver\remote\webdriver.py", line 321, in execute
    self.error_handler.check_response(response)
  File "E:\Python3\lib\site-packages\selenium\webdriver\remote\errorhandler.py", line 242, in check_response
    raise exception_class(message, screen, stacktrace)
selenium.common.exceptions.TimeoutException: Message: timeout
  (Session info: chrome=73.0.3683.103)
  (Driver info: chromedriver=2.36.540470 (e522d04694c7ebea4ba8821272dbef4f9b818c91),platform=Windows NT 6.1.7601 SP1 x86_64)

ERROR    common.basepage:basepage.py:186 网页截屏失败！
Traceback (most recent call last):
  File "D:\B2B\common\basepage.py", line 28, in wait_eleVisible
    WebDriverWait(self.driver,timeout,frequency).until(EC.visibility_of_element_located(loc))
  File "E:\Python3\lib\site-packages\selenium\webdriver\support\wait.py", line 71, in until
    value = method(self._driver)
  File "E:\Python3\lib\site-packages\selenium\webdriver\support\expected_conditions.py", line 128, in __call__
    return _element_if_visible(_find_element(driver, self.locator))
  File "E:\Python3\lib\site-packages\selenium\webdriver\support\expected_conditions.py", line 415, in _find_element
    raise e
  File "E:\Python3\lib\site-packages\selenium\webdriver\support\expected_conditions.py", line 411, in _find_element
    return driver.find_element(*by)
  File "E:\Python3\lib\site-packages\selenium\webdriver\remote\webdriver.py", line 978, in find_element
    'value': value})['value']
  File "E:\Python3\lib\site-packages\selenium\webdriver\remote\webdriver.py", line 321, in execute
    self.error_handler.check_response(response)
  File "E:\Python3\lib\site-packages\selenium\webdriver\remote\errorhandler.py", line 242, in check_response
    raise exception_class(message, screen, stacktrace)
selenium.common.exceptions.TimeoutException: Message: timeout
  (Session info: chrome=73.0.3683.103)
  (Driver info: chromedriver=2.36.540470 (e522d04694c7ebea4ba8821272dbef4f9b818c91),platform=Windows NT 6.1.7601 SP1 x86_64)


During handling of the above exception, another exception occurred:

Traceback (most recent call last):
  File "D:\B2B\common\basepage.py", line 183, in save_web_screenshot
    self.driver.save_screenshot(screenshot_dir +"/" + filepath)
  File "E:\Python3\lib\site-packages\selenium\webdriver\remote\webdriver.py", line 1055, in save_screenshot
    return self.get_screenshot_as_file(filename)
  File "E:\Python3\lib\site-packages\selenium\webdriver\remote\webdriver.py", line 1032, in get_screenshot_as_file
    png = self.get_screenshot_as_png()
  File "E:\Python3\lib\site-packages\selenium\webdriver\remote\webdriver.py", line 1064, in get_screenshot_as_png
    return base64.b64decode(self.get_screenshot_as_base64().encode('ascii'))
  File "E:\Python3\lib\site-packages\selenium\webdriver\remote\webdriver.py", line 1074, in get_screenshot_as_base64
    return self.execute(Command.SCREENSHOT)['value']
  File "E:\Python3\lib\site-packages\selenium\webdriver\remote\webdriver.py", line 321, in execute
    self.error_handler.check_response(response)
  File "E:\Python3\lib\site-packages\selenium\webdriver\remote\errorhandler.py", line 242, in check_response
    raise exception_class(message, screen, stacktrace)
selenium.common.exceptions.TimeoutException: Message: timeout
  (Session info: chrome=73.0.3683.103)
  (Driver info: chromedriver=2.36.540470 (e522d04694c7ebea4ba8821272dbef4f9b818c91),platform=Windows NT 6.1.7601 SP1 x86_64)